Workbook
Name \0: #REF!
Name b_dist: #REF!
Name b_pourb: #REF!
Name b_recus: #REF!
Name b_ventes: #REF!
Name d_debut_fin: #N/A
Name d_debut_retour: #N/A
Name d_depart_fin: #REF!
Name m_imprimer: #REF!
Name m_recherche: #REF!
Name macro_de_vidange: #REF!
Name macro_debut: #REF!
Name recherche: #N/A

Sheet Feuil1
A1: Compagnie | B1: Matricule | D1: Nom, prénom | E1: No relevé | F1: Période | G1: TRAV 1 | H1: TRAV 2 | I1: TRAV 3 | J1: TRAV 4 | K1: TRAV 5 | L1: TRAV 6 | M1: G730(Montant) | N1: G731(Montant) | O1: G809(Montant) | P1: G(Montant)
A2: ** | M2: VENTE TOT. | N2: POURB BRUT | O2: POURB.DECLARES | P2: pourb attribué
A3: 8643 | B3: =+Sommaire!A9 -> 5889 | C3: =RIGHT(CONCATENATE("000",B3),6) -> 005889 | D3: =+Sommaire!B9 -> Abou Assaly Linda | E3: 0 | F3: 46060 | M3: =+Sommaire!BI9 -> 261.81 | N3: =+Sommaire!BJ9 -> 26.18 | O3: =+Sommaire!BO9 -> 26.18 | P3: =+Sommaire!BP9 -> 0
A4: 8643 | B4: =+Sommaire!A10 -> 5674 | C4: =RIGHT(CONCATENATE("000",B4),6) -> 005674 | D4: =+Sommaire!B10 -> BALZAGE, Julien | E4: 0 | F4: 46060 | M4: =+Sommaire!BI10 -> 8639.86 | N4: =+Sommaire!BJ10 -> 861.84 | O4: =+Sommaire!BO10 -> 861.84 | P4: =+Sommaire!BP10 -> 0
A5: 8643 | B5: =+Sommaire!A11 -> 92704 | C5: =RIGHT(CONCATENATE("000",B5),6) -> 092704 | D5: =+Sommaire!B11 -> Belanger Danielle | E5: 0 | F5: 46060 | M5: =+Sommaire!BI11 -> 0 | N5: =+Sommaire!BJ11 -> 0 | O5: =+Sommaire!BO11 -> 0 | P5: =+Sommaire!BP11 -> 0
A6: 8643 | B6: =+Sommaire!A12 -> 93512 | C6: =RIGHT(CONCATENATE("000",B6),6) -> 093512 | D6: =+Sommaire!B12 -> Bergeron Josee | E6: 0 | F6: 46060 | M6: =+Sommaire!BI12 -> 0 | N6: =+Sommaire!BJ12 -> 0 | O6: =+Sommaire!BO12 -> 0 | P6: =+Sommaire!BP12 -> 0
A7: 8643 | B7: =+Sommaire!A13 -> 5274 | C7: =RIGHT(CONCATENATE("000",B7),6) -> 005274 | D7: =+Sommaire!B13 -> Bernachez, Stephane | E7: 0 | F7: 46060 | M7: =+Sommaire!BI13 -> 9143.55 | N7: =+Sommaire!BJ13 -> 916.6 | O7: =+Sommaire!BO13 -> 916.6 | P7: =+Sommaire!BP13 -> 0
A8: 8643 | B8: =+Sommaire!A14 -> 5749 | C8: =RIGHT(CONCATENATE("000",B8),6) -> 005749 | D8: =+Sommaire!B14 -> Bertrand Nicolas | E8: 0 | F8: 46060 | M8: =+Sommaire!BI14 -> 10907.48 | N8: =+Sommaire!BJ14 -> 1259.83 | O8: =+Sommaire!BO14 -> 1259.83 | P8: =+Sommaire!BP14 -> 0
A9: 8643 | B9: =+Sommaire!A15 -> 91663 | C9: =RIGHT(CONCATENATE("000",B9),6) -> 091663 | D9: =+Sommaire!B15 -> Bordeleau Lyne | E9: 0 | F9: 46060 | M9: =+Sommaire!BI15 -> 0 | N9: =+Sommaire!BJ15 -> 0 | O9: =+Sommaire!BO15 -> 0 | P9: =+Sommaire!BP15 -> 0
A10: 8643 | B10: =+Sommaire!A16 -> 5515 | C10: =RIGHT(CONCATENATE("000",B10),6) -> 005515 | D10: =+Sommaire!B16 -> Campos. Plinio Testa | E10: 0 | F10: 46060 | M10: =+Sommaire!BI16 -> 13340.81 | N10: =+Sommaire!BJ16 -> 1331.81 | O10: =+Sommaire!BO16 -> 1331.81 | P10: =+Sommaire!BP16 -> 0
A11: 8643 | B11: =+Sommaire!A17 -> 5361 | C11: =RIGHT(CONCATENATE("000",B11),6) -> 005361 | D11: =+Sommaire!B17 -> Cecile patricia | E11: 0 | F11: 46060 | M11: =+Sommaire!BI17 -> 5580.38 | N11: =+Sommaire!BJ17 -> 560.72 | O11: =+Sommaire!BO17 -> 560.72 | P11: =+Sommaire!BP17 -> 0
A12: 8643 | B12: =+Sommaire!A18 -> 4219 | C12: =RIGHT(CONCATENATE("000",B12),6) -> 004219 | D12: =+Sommaire!B18 -> Chartier Marie-Eve | E12: 0 | F12: 46060 | M12: =+Sommaire!BI18 -> 0 | N12: =+Sommaire!BJ18 -> 0 | O12: =+Sommaire!BO18 -> 0 | P12: =+Sommaire!BP18 -> 0
A13: 8643 | B13: =+Sommaire!A19 -> 3767 | C13: =RIGHT(CONCATENATE("000",B13),6) -> 003767 | D13: =+Sommaire!B19 -> Dagenais Julie | E13: 0 | F13: 46060 | M13: =+Sommaire!BI19 -> 545.96 | N13: =+Sommaire!BJ19 -> 54.45 | O13: =+Sommaire!BO19 -> 54.45 | P13: =+Sommaire!BP19 -> 0
A14: 8643 | B14: =+Sommaire!A20 -> 5742 | C14: =RIGHT(CONCATENATE("000",B14),6) -> 005742 | D14: =+Sommaire!B20 -> Di Blasio Bianca | E14: 0 | F14: 46060 | M14: =+Sommaire!BI20 -> 0 | N14: =+Sommaire!BJ20 -> 0 | O14: =+Sommaire!BO20 -> 0 | P14: =+Sommaire!BP20 -> 0
... A60: 8646 | B60: =+Sommaire!A66 -> 3977 | C60: =RIGHT(CONCATENATE("000",B60),6) -> 003977 | D60: =+Sommaire!B66 -> Yelle Caroline | E60: 3 | F60: 46060 | M60: =+Sommaire!BI66 -> 0 | N60: =+Sommaire!BJ66 -> 0 | O60: =+Sommaire!BO66 -> 0 | P60: =+Sommaire!BP66 -> 0
M61: =SUBTOTAL(9,M3:M60) -> 121232.95 | N61: =SUBTOTAL(9,N3:N60) -> 12278.86 | O61: =SUBTOTAL(9,O3:O60) -> 12278.86 | P61: =SUBTOTAL(9,P3:P60) -> 0
M62: =+Sommaire!BI68 -> 121232.95 | N62: =+Sommaire!BJ68 -> 12278.86 | O62: =+Sommaire!BO68 -> 12278.86 | P62: =+Sommaire!BP68 -> 0
F63: Validation | M63: =+M61-M62 -> 0 | N63: =+N61-N62 -> 0 | O63: =+O61-O62 -> 0 | P63: =+P61-P62 -> 0

Sheet Sommaire
A1: HÔTEL SHERATON LAVAL
A2: REGISTRE DES POURBOIRES
C4: Période | BH4: 45990 | BL4: =+BD5 -> 46060
D5: 46047 | H5: =+D5+1 -> 46048 | L5: =1+H5 -> 46049 | P5: =1+L5 -> 46050 | T5: =1+P5 -> 46051 | X5: =1+T5 -> 46052 | AB5: =1+X5 -> 46053 | AF5: =AB5+1 -> 46054 | AJ5: =1+AF5 -> 46055 | AN5: =1+AJ5 -> 46056 | AR5: =1+AN5 -> 46057 | AV5: =1+AR5 -> 46058 | AZ5: =1+AV5 -> 46059 | BD5: =1+AZ5 -> 46060 | BH5: Ventes | BI5: Pourb | BJ5: Dist | BK5: Reçus
A6: #emp | B6: nom | C6: # clé | D6: Ventes | E6: Pourb | F6: Dist | G6: Reçus | H6: Ventes | I6: Pourb | J6: Dist | K6: Reçus | L6: Ventes | M6: Pourb | N6: Dist | O6: Reçus | P6: Ventes | Q6: Pourb | R6: Dist | S6: Reçus | T6: Ventes | U6: Pourb | V6: Dist | W6: Reçus | X6: Ventes | Y6: Pourb | Z6: Dist | AA6: Reçus | AB6: Ventes | AC6: Pourb | AD6: Dist | AE6: Reçus | AF6: Ventes | AG6: Pourb | AH6: Dist | AI6: Reçus | AJ6: Ventes | AK6: Pourb | AL6: Dist | AM6: Reçus | AN6: Ventes | AO6: Pourb | AP6: Dist | AQ6: Reçus | AR6: Ventes | AS6: Pourb | AT6: Dist | AU6: Reçus | AV6: Ventes | AW6: Pourb | AX6: Dist | AY6: Reçus | AZ6: Ventes | BA6: Pourb | BB6: Dist | BC6: Reçus | BD6: Ventes | BE6: Pourb | BF6: Dist | BG6: Reçus | BI6: Ventes | BJ6: Pourboires bruts | BK6: Pourboires redistribués | BL6: Pourboires reçus | BM6: Net 1ere semaine | BN6: Net 2ieme semaine | BO6: Pourboires nets | BP6: Montant Attribué
BI7: =+D7+H7+L7+P7+T7+X7+AB7+AF7+AJ7+AN7+AR7+AV7+AZ7+BD7 -> 0 | BJ7: =+E7+I7+M7+Q7+U7+Y7+AC7+AG7+AK7+AO7+AS7+AW7+BA7+BE7 -> 0 | BK7: =+F7+J7+N7+R7+V8+Z7+AD7+AH7+AL7+AP7+AT7+AX7+BB7+BF7 -> 0 | BL7: =+G7+K7+O7+S7+W7+AA7+AE7+AI7+AM7+AQ7+AU7+AY7+BC7+BG7 -> 0 | BM7: =+E7-F7+G7+I7-J7+K7+M7-N7+O7+Q7-R7+S7+U7-V8+W7+Y7-Z7+AA7+AC7-AD7+AE7 -> 0 | BN7: =+AG7-AH7+AI7+AK7-AL7+AM7+AO7-AP7+AQ7+AS7-AT7+AU7+AW7-AX7+AY7+BA7-BB7+BC7+BE7-BF7+BG7 -> 0 | BO7: =BJ7-BK7+BL7 -> 0 | BP7: =IF((+BI7*0.08)<BJ7,0,(+BI7*0.08)-BJ7) -> 0 | BQ7: =IF(BI7<>0,+BJ7/BI7,0) -> 0
BI8: =+D8+H8+L8+P8+T8+X8+AB8+AF8+AJ8+AN8+AR8+AV8+AZ8+BD8 -> 0 | BJ8: =+E8+I8+M8+Q8+U8+Y8+AC8+AG8+AK8+AO8+AS8+AW8+BA8+BE8 -> 0 | BK8: =+F8+J8+N8+R8+V9+Z8+AD8+AH8+AL8+AP8+AT8+AX8+BB8+BF8 -> 0 | BL8: =+G8+K8+O8+S8+W8+AA8+AE8+AI8+AM8+AQ8+AU8+AY8+BC8+BG8 -> 0 | BM8: =+E8-F8+G8+I8-J8+K8+M8-N8+O8+Q8-R8+S8+U8-V9+W8+Y8-Z8+AA8+AC8-AD8+AE8 -> 0 | BN8: =+AG8-AH8+AI8+AK8-AL8+AM8+AO8-AP8+AQ8+AS8-AT8+AU8+AW8-AX8+AY8+BA8-BB8+BC8+BE8-BF8+BG8 -> 0 | BO8: =BJ8-BK8+BL8 -> 0 | BP8: =IF((+BI8*0.08)<BJ8,0,(+BI8*0.08)-BJ8) -> 0 | BQ8: =IF(BI8<>0,+BJ8/BI8,0) -> 0
A9: 5889 | B9: Abou Assaly Linda | D9: =261.81 -> 261.81 | E9: 26.18 | BI9: =+D9+H9+L9+P9+T9+X9+AB9+AF9+AJ9+AN9+AR9+AV9+AZ9+BD9 -> 261.81 | BJ9: =+E9+I9+M9+Q9+U9+Y9+AC9+AG9+AK9+AO9+AS9+AW9+BA9+BE9 -> 26.18 | BK9: =+F9+J9+N9+R9+V10+Z9+AD9+AH9+AL9+AP9+AT9+AX9+BB9+BF9 -> 0 | BL9: =+G9+K9+O9+S9+W9+AA9+AE9+AI9+AM9+AQ9+AU9+AY9+BC9+BG9 -> 0 | BM9: =+E9-F9+G9+I9-J9+K9+M9-N9+O9+Q9-R9+S9+U9-V10+W9+Y9-Z9+AA9+AC9-AD9+AE9 -> 26.18 | BN9: =+AG9-AH9+AI9+AK9-AL9+AM9+AO9-AP9+AQ9+AS9-AT9+AU9+AW9-AX9+AY9+BA9-BB9+BC9+BE9-BF9+BG9 -> 0 | BO9: =BJ9-BK9+BL9 -> 26.18 | BP9: =IF((+BI9*0.08)<BJ9,0,(+BI9*0.08)-BJ9) -> 0 | BQ9: =IF(BI9<>0,+BJ9/BI9,0) -> 0.09999618
A10: 5674 | B10: BALZAGE, Julien | D10: =708.48 -> 708.48 | E10: =70.84 -> 70.84 | L10: 200 | M10: 20 | T10: 1376.5 | U10: 137 | X10: 1681.39 | Y10: 168 | AB10: 2202.97 | AC10: 220 | AF10: 1362.83 | AG10: 136 | AZ10: =1107.69 -> 1107.69 | BA10: =110 -> 110 | BI10: =+D10+H10+L10+P10+T10+X10+AB10+AF10+AJ10+AN10+AR10+AV10+AZ10+BD10 -> 8639.86 | BJ10: =+E10+I10+M10+Q10+U10+Y10+AC10+AG10+AK10+AO10+AS10+AW10+BA10+BE10 -> 861.84 | BK10: =+F10+J10+N10+R10+V11+Z10+AD10+AH10+AL10+AP10+AT10+AX10+BB10+BF10 -> 0 | BL10: =+G10+K10+O10+S10+W10+AA10+AE10+AI10+AM10+AQ10+AU10+AY10+BC10+BG10 -> 0 | BM10: =+E10-F10+G10+I10-J10+K10+M10-N10+O10+Q10-R10+S10+U10-V11+W10+Y10-Z10+AA10+AC10-AD10+AE10 -> 615.84 | BN10: =+AG10-AH10+AI10+AK10-AL10+AM10+AO10-AP10+AQ10+AS10-AT10+AU10+AW10-AX10+AY10+BA10-BB10+BC10+BE10-BF10+BG10 -> 246 | BO10: =BJ10-BK10+BL10 -> 861.84 | BP10: =IF((+BI10*0.08)<BJ10,0,(+BI10*0.08)-BJ10) -> 0 | BQ10: =IF(BI10<>0,+BJ10/BI10,0) -> 0.099751616
A11: 92704 | B11: Belanger Danielle | BI11: =+D11+H11+L11+P11+T11+X11+AB11+AF11+AJ11+AN11+AR11+AV11+AZ11+BD11 -> 0 | BJ11: =+E11+I11+M11+Q11+U11+Y11+AC11+AG11+AK11+AO11+AS11+AW11+BA11+BE11 -> 0 | BK11: =+F11+J11+N11+R11+V12+Z11+AD11+AH11+AL11+AP11+AT11+AX11+BB11+BF11 -> 0 | BL11: =+G11+K11+O11+S11+W11+AA11+AE11+AI11+AM11+AQ11+AU11+AY11+BC11+BG11 -> 0 | BM11: =+E11-F11+G11+I11-J11+K11+M11-N11+O11+Q11-R11+S11+U11-V12+W11+Y11-Z11+AA11+AC11-AD11+AE11 -> 0 | BN11: =+AG11-AH11+AI11+AK11-AL11+AM11+AO11-AP11+AQ11+AS11-AT11+AU11+AW11-AX11+AY11+BA11-BB11+BC11+BE11-BF11+BG11 -> 0 | BO11: =BJ11-BK11+BL11 -> 0 | BP11: =IF((+BI11*0.08)<BJ11,0,(+BI11*0.08)-BJ11) -> 0 | BQ11: =IF(BI11<>0,+BJ11/BI11,0) -> 0
A12: 93512 | B12: Bergeron Josee | BI12: =+D12+H12+L12+P12+T12+X12+AB12+AF12+AJ12+AN12+AR12+AV12+AZ12+BD12 -> 0 | BJ12: =+E12+I12+M12+Q12+U12+Y12+AC12+AG12+AK12+AO12+AS12+AW12+BA12+BE12 -> 0 | BK12: =+F12+J12+N12+R12+V13+Z12+AD12+AH12+AL12+AP12+AT12+AX12+BB12+BF12 -> 0 | BL12: =+G12+K12+O12+S12+W12+AA12+AE12+AI12+AM12+AQ12+AU12+AY12+BC12+BG12 -> 0 | BM12: =+E12-F12+G12+I12-J12+K12+M12-N12+O12+Q12-R12+S12+U12-V13+W12+Y12-Z12+AA12+AC12-AD12+AE12 -> 0 | BN12: =+AG12-AH12+AI12+AK12-AL12+AM12+AO12-AP12+AQ12+AS12-AT12+AU12+AW12-AX12+AY12+BA12-BB12+BC12+BE12-BF12+BG12 -> 0 | BO12: =BJ12-BK12+BL12 -> 0 | BP12: =IF((+BI12*0.08)<BJ12,0,(+BI12*0.08)-BJ12) -> 0 | BQ12: =IF(BI12<>0,+BJ12/BI12,0) -> 0
A13: 5274 | B13: Bernachez, Stephane | D13: =261.81+2321.48 -> 2583.29 | E13: =26.18+232 -> 258.18 | H13: 534.8 | I13: 54 | L13: =285.5+229.25 -> 514.75 | M13: =29+22.92 -> 51.92 | P13: 501.91 | Q13: 50.19 | T13: 270.42 | U13: 27 | AF13: =821.76+1622.05 -> 2443.81 | AG13: =82.1+162 -> 244.1 | AJ13: =298.5 -> 298.5 | AK13: =29.85 -> 29.85 | AN13: =580.87+251.83 -> 832.7 | AO13: =59+25.18 -> 84.18 | AR13: 330.66 | AS13: 33 | AV13: =251.83+580.88 -> 832.71 | AW13: =25.18+59 -> 84.18 | BI13: =+D13+H13+L13+P13+T13+X13+AB13+AF13+AJ13+AN13+AR13+AV13+AZ13+BD13 -> 9143.55 | BJ13: =+E13+I13+M13+Q13+U13+Y13+AC13+AG13+AK13+AO13+AS13+AW13+BA13+BE13 -> 916.6 | BK13: =+F13+J13+N13+R13+V14+Z13+AD13+AH13+AL13+AP13+AT13+AX13+BB13+BF13 -> 0 | BL13: =+G13+K13+O13+S13+W13+AA13+AE13+AI13+AM13+AQ13+AU13+AY13+BC13+BG13 -> 0 | BM13: =+E13-F13+G13+I13-J13+K13+M13-N13+O13+Q13-R13+S13+U13-V14+W13+Y13-Z13+AA13+AC13-AD13+AE13 -> 441.29 | BN13: =+AG13-AH13+AI13+AK13-AL13+AM13+AO13-AP13+AQ13+AS13-AT13+AU13+AW13-AX13+AY13+BA13-BB13+BC13+BE13-BF13+BG13 -> 475.31 | BO13: =BJ13-BK13+BL13 -> 916.6 | BP13: =IF((+BI13*0.08)<BJ13,0,(+BI13*0.08)-BJ13) -> 0 | BQ13: =IF(BI13<>0,+BJ13/BI13,0) -> 0.10024553
A14: 5749 | B14: Bertrand Nicolas | H14: 1248.12 | I14: 124 | L14: 2002.5 | M14: 200 | P14: 1081.33 | Q14: 108 | AB14: 2202.97 | AC14: 220 | AJ14: 716.25 | AK14: 71 | AN14: 793.88 | AO14: 79 | AR14: =748.55 -> 748.55 | AS14: 74 | AV14: 793.88 | AW14: 251.83 | BD14: 1320 | BE14: 132 | BI14: =+D14+H14+L14+P14+T14+X14+AB14+AF14+AJ14+AN14+AR14+AV14+AZ14+BD14 -> 10907.48 | BJ14: =+E14+I14+M14+Q14+U14+Y14+AC14+AG14+AK14+AO14+AS14+AW14+BA14+BE14 -> 1259.83 | BK14: =+F14+J14+N14+R14+V15+Z14+AD14+AH14+AL14+AP14+AT14+AX14+BB14+BF14 -> 0 | BL14: =+G14+K14+O14+S14+W14+AA14+AE14+AI14+AM14+AQ14+AU14+AY14+BC14+BG14 -> 0 | BM14: =+E14-F14+G14+I14-J14+K14+M14-N14+O14+Q14-R14+S14+U14-V15+W14+Y14-Z14+AA14+AC14-AD14+AE14 -> 652 | BN14: =+AG14-AH14+AI14+AK14-AL14+AM14+AO14-AP14+AQ14+AS14-AT14+AU14+AW14-AX14+AY14+BA14-BB14+BC14+BE14-BF14+BG14 -> 607.83 | BO14: =BJ14-BK14+BL14 -> 1259.83 | BP14: =IF((+BI14*0.08)<BJ14,0,(+BI14*0.08)-BJ14) -> 0 | BQ14: =IF(BI14<>0,+BJ14/BI14,0) -> 0.11550147
A15: 91663 | B15: Bordeleau Lyne | BI15: =+D15+H15+L15+P15+T15+X15+AB15+AF15+AJ15+AN15+AR15+AV15+AZ15+BD15 -> 0 | BJ15: =+E15+I15+M15+Q15+U15+Y15+AC15+AG15+AK15+AO15+AS15+AW15+BA15+BE15 -> 0 | BK15: =+F15+J15+N15+R15+V16+Z15+AD15+AH15+AL15+AP15+AT15+AX15+BB15+BF15 -> 0 | BL15: =+G15+K15+O15+S15+W15+AA15+AE15+AI15+AM15+AQ15+AU15+AY15+BC15+BG15 -> 0 | BM15: =+E15-F15+G15+I15-J15+K15+M15-N15+O15+Q15-R15+S15+U15-V16+W15+Y15-Z15+AA15+AC15-AD15+AE15 -> 0 | BN15: =+AG15-AH15+AI15+AK15-AL15+AM15+AO15-AP15+AQ15+AS15-AT15+AU15+AW15-AX15+AY15+BA15-BB15+BC15+BE15-BF15+BG15 -> 0 | BO15: =BJ15-BK15+BL15 -> 0 | BP15: =IF((+BI15*0.08)<BJ15,0,(+BI15*0.08)-BJ15) -> 0 | BQ15: =IF(BI15<>0,+BJ15/BI15,0) -> 0
A16: 5515 | B16: Campos. Plinio Testa | D16: =218.19+2321.48 -> 2539.67 | E16: =21.81+232 -> 253.81 | P16: 890.54 | Q16: 89 | T16: 1376.5 | U16: 137 | X16: 1681.39 | Y16: 168 | AB16: 2202.97 | AC16: 220 | AF16: 1622.05 | AG16: 162 | AR16: 600 | AS16: 60 | AZ16: =1107.69 -> 1107.69 | BA16: =110 -> 110 | BD16: 1320 | BE16: 132 | BI16: =+D16+H16+L16+P16+T16+X16+AB16+AF16+AJ16+AN16+AR16+AV16+AZ16+BD16 -> 13340.81 | BJ16: =+E16+I16+M16+Q16+U16+Y16+AC16+AG16+AK16+AO16+AS16+AW16+BA16+BE16 -> 1331.81 | BK16: =+F16+J16+N16+R16+V17+Z16+AD16+AH16+AL16+AP16+AT16+AX16+BB16+BF16 -> 0 | BL16: =+G16+K16+O16+S16+W16+AA16+AE16+AI16+AM16+AQ16+AU16+AY16+BC16+BG16 -> 0 | BM16: =+E16-F16+G16+I16-J16+K16+M16-N16+O16+Q16-R16+S16+U16-V17+W16+Y16-Z16+AA16+AC16-AD16+AE16 -> 867.81 | BN16: =+AG16-AH16+AI16+AK16-AL16+AM16+AO16-AP16+AQ16+AS16-AT16+AU16+AW16-AX16+AY16+BA16-BB16+BC16+BE16-BF16+BG16 -> 464 | BO16: =BJ16-BK16+BL16 -> 1331.81 | BP16: =IF((+BI16*0.08)<BJ16,0,(+BI16*0.08)-BJ16) -> 0 | BQ16: =IF(BI16<>0,+BJ16/BI16,0) -> 0.09982977
A17: 5361 | B17: Cecile patricia | L17: =285.5+229.25 -> 514.75 | M17: =29+22.92 -> 51.92 | P17: 501.91 | Q17: 50.19 | T17: =270.41+767.75 -> 1038.16 | U17: =27+76.77 -> 103.77 | X17: =303.11+371.21 -> 674.32 | Y17: =30.31+37.42 -> 67.73 | AJ17: =298.5+374.88 -> 673.38 | AK17: =29.85+37.48 -> 67.33 | AN17: =580.88+251.83 -> 832.71 | AO17: =59+25.18 -> 84.18 | AV17: =251.83+580.88 -> 832.71 | AW17: =25.18+59 -> 84.18 | AZ17: =214.25+298.19 -> 512.44 | BA17: =21.42+30 -> 51.42 | BI17: =+D17+H17+L17+P17+T17+X17+AB17+AF17+AJ17+AN17+AR17+AV17+AZ17+BD17 -> 5580.38 | BJ17: =+E17+I17+M17+Q17+U17+Y17+AC17+AG17+AK17+AO17+AS17+AW17+BA17+BE17 -> 560.72 | BK17: =+F17+J17+N17+R17+V18+Z17+AD17+AH17+AL17+AP17+AT17+AX17+BB17+BF17 -> 0 | BL17: =+G17+K17+O17+S17+W17+AA17+AE17+AI17+AM17+AQ17+AU17+AY17+BC17+BG17 -> 0 | BM17: =+E17-F17+G17+I17-J17+K17+M17-N17+O17+Q17-R17+S17+U17-V18+W17+Y17-Z17+AA17+AC17-AD17+AE17 -> 273.61 | BN17: =+AG17-AH17+AI17+AK17-AL17+AM17+AO17-AP17+AQ17+AS17-AT17+AU17+AW17-AX17+AY17+BA17-BB17+BC17+BE17-BF17+BG17 -> 287.11 | BO17: =BJ17-BK17+BL17 -> 560.72 | BP17: =IF((+BI17*0.08)<BJ17,0,(+BI17*0.08)-BJ17) -> 0 | BQ17: =IF(BI17<>0,+BJ17/BI17,0) -> 0.10048061
A18: 4219 | B18: Chartier Marie-Eve | BI18: =+D18+H18+L18+P18+T18+X18+AB18+AF18+AJ18+AN18+AR18+AV18+AZ18+BD18 -> 0 | BJ18: =+E18+I18+M18+Q18+U18+Y18+AC18+AG18+AK18+AO18+AS18+AW18+BA18+BE18 -> 0 | BK18: =+F18+J18+N18+R18+V19+Z18+AD18+AH18+AL18+AP18+AT18+AX18+BB18+BF18 -> 0 | BL18: =+G18+K18+O18+S18+W18+AA18+AE18+AI18+AM18+AQ18+AU18+AY18+BC18+BG18 -> 0 | BM18: =+E18-F18+G18+I18-J18+K18+M18-N18+O18+Q18-R18+S18+U18-V19+W18+Y18-Z18+AA18+AC18-AD18+AE18 -> 0 | BN18: =+AG18-AH18+AI18+AK18-AL18+AM18+AO18-AP18+AQ18+AS18-AT18+AU18+AW18-AX18+AY18+BA18-BB18+BC18+BE18-BF18+BG18 -> 0 | BO18: =BJ18-BK18+BL18 -> 0 | BP18: =IF((+BI18*0.08)<BJ18,0,(+BI18*0.08)-BJ18) -> 0 | BQ18: =IF(BI18<>0,+BJ18/BI18,0) -> 0
A19: 3767 | B19: Dagenais Julie | D19: =427.25 -> 427.25 | E19: 42.75 | T19: 118.71 | U19: 11.7 | BI19: =+D19+H19+L19+P19+T19+X19+AB19+AF19+AJ19+AN19+AR19+AV19+AZ19+BD19 -> 545.96 | BJ19: =+E19+I19+M19+Q19+U19+Y19+AC19+AG19+AK19+AO19+AS19+AW19+BA19+BE19 -> 54.45 | BK19: =+F19+J19+N19+R19+V20+Z19+AD19+AH19+AL19+AP19+AT19+AX19+BB19+BF19 -> 0 | BL19: =+G19+K19+O19+S19+W19+AA19+AE19+AI19+AM19+AQ19+AU19+AY19+BC19+BG19 -> 0 | BM19: =+E19-F19+G19+I19-J19+K19+M19-N19+O19+Q19-R19+S19+U19-V20+W19+Y19-Z19+AA19+AC19-AD19+AE19 -> 54.45 | BN19: =+AG19-AH19+AI19+AK19-AL19+AM19+AO19-AP19+AQ19+AS19-AT19+AU19+AW19-AX19+AY19+BA19-BB19+BC19+BE19-BF19+BG19 -> 0 | BO19: =BJ19-BK19+BL19 -> 54.45 | BP19: =IF((+BI19*0.08)<BJ19,0,(+BI19*0.08)-BJ19) -> 0 | BQ19: =IF(BI19<>0,+BJ19/BI19,0) -> 0.099732581
A20: 5742 | B20: Di Blasio Bianca | BI20: =+D20+H20+L20+P20+T20+X20+AB20+AF20+AJ20+AN20+AR20+AV20+AZ20+BD20 -> 0 | BJ20: =+E20+I20+M20+Q20+U20+Y20+AC20+AG20+AK20+AO20+AS20+AW20+BA20+BE20 -> 0 | BK20: =+F20+J20+N20+R20+V21+Z20+AD20+AH20+AL20+AP20+AT20+AX20+BB20+BF20 -> 0 | BL20: =+G20+K20+O20+S20+W20+AA20+AE20+AI20+AM20+AQ20+AU20+AY20+BC20+BG20 -> 0 | BM20: =+E20-F20+G20+I20-J20+K20+M20-N20+O20+Q20-R20+S20+U20-V21+W20+Y20-Z20+AA20+AC20-AD20+AE20 -> 0 | BN20: =+AG20-AH20+AI20+AK20-AL20+AM20+AO20-AP20+AQ20+AS20-AT20+AU20+AW20-AX20+AY20+BA20-BB20+BC20+BE20-BF20+BG20 -> 0 | BO20: =BJ20-BK20+BL20 -> 0 | BP20: =IF((+BI20*0.08)<BJ20,0,(+BI20*0.08)-BJ20) -> 0 | BQ20: =IF(BI20<>0,+BJ20/BI20,0) -> 0
A21: 4290 | B21: Difrusia Costantino | D21: =218.18+2321.48 -> 2539.66 | E21: =21.81+232 -> 253.81 | AB21: 2202.97 | AC21: 220 | BI21: =+D21+H21+L21+P21+T21+X21+AB21+AF21+AJ21+AN21+AR21+AV21+AZ21+BD21 -> 4742.63 | BJ21: =+E21+I21+M21+Q21+U21+Y21+AC21+AG21+AK21+AO21+AS21+AW21+BA21+BE21 -> 473.81 | BK21: =+F21+J21+N21+R21+V22+Z21+AD21+AH21+AL21+AP21+AT21+AX21+BB21+BF21 -> 0 | BL21: =+G21+K21+O21+S21+W21+AA21+AE21+AI21+AM21+AQ21+AU21+AY21+BC21+BG21 -> 0 | BM21: =+E21-F21+G21+I21-J21+K21+M21-N21+O21+Q21-R21+S21+U21-V22+W21+Y21-Z21+AA21+AC21-AD21+AE21 -> 473.81 | BN21: =+AG21-AH21+AI21+AK21-AL21+AM21+AO21-AP21+AQ21+AS21-AT21+AU21+AW21-AX21+AY21+BA21-BB21+BC21+BE21-BF21+BG21 -> 0 | BO21: =BJ21-BK21+BL21 -> 473.81 | BP21: =IF((+BI21*0.08)<BJ21,0,(+BI21*0.08)-BJ21) -> 0 | BQ21: =IF(BI21<>0,+BJ21/BI21,0) -> 0.099904483
A22: 3796 | B22: Dupont Frederick | BI22: =+D22+H22+L22+P22+T22+X22+AB22+AF22+AJ22+AN22+AR22+AV22+AZ22+BD22 -> 0 | BJ22: =+E22+I22+M22+Q22+U22+Y22+AC22+AG22+AK22+AO22+AS22+AW22+BA22+BE22 -> 0 | BK22: =+F22+J22+N22+R22+V23+Z22+AD22+AH22+AL22+AP22+AT22+AX22+BB22+BF22 -> 0 | BL22: =+G22+K22+O22+S22+W22+AA22+AE22+AI22+AM22+AQ22+AU22+AY22+BC22+BG22 -> 0 | BM22: =+E22-F22+G22+I22-J22+K22+M22-N22+O22+Q22-R22+S22+U22-V23+W22+Y22-Z22+AA22+AC22-AD22+AE22 -> 0 | BN22: =+AG22-AH22+AI22+AK22-AL22+AM22+AO22-AP22+AQ22+AS22-AT22+AU22+AW22-AX22+AY22+BA22-BB22+BC22+BE22-BF22+BG22 -> 0 | BO22: =BJ22-BK22+BL22 -> 0 | BP22: =IF((+BI22*0.08)<BJ22,0,(+BI22*0.08)-BJ22) -> 0 | BQ22: =IF(BI22<>0,+BJ22/BI22,0) -> 0
A23: 90333 | B23: Emond Pierre | BI23: =+D23+H23+L23+P23+T23+X23+AB23+AF23+AJ23+AN23+AR23+AV23+AZ23+BD23 -> 0 | BJ23: =+E23+I23+M23+Q23+U23+Y23+AC23+AG23+AK23+AO23+AS23+AW23+BA23+BE23 -> 0 | BK23: =+F23+J23+N23+R23+V24+Z23+AD23+AH23+AL23+AP23+AT23+AX23+BB23+BF23 -> 0 | BL23: =+G23+K23+O23+S23+W23+AA23+AE23+AI23+AM23+AQ23+AU23+AY23+BC23+BG23 -> 0 | BM23: =+E23-F23+G23+I23-J23+K23+M23-N23+O23+Q23-R23+S23+U23-V24+W23+Y23-Z23+AA23+AC23-AD23+AE23 -> 0 | BN23: =+AG23-AH23+AI23+AK23-AL23+AM23+AO23-AP23+AQ23+AS23-AT23+AU23+AW23-AX23+AY23+BA23-BB23+BC23+BE23-BF23+BG23 -> 0 | BO23: =BJ23-BK23+BL23 -> 0 | BP23: =IF((+BI23*0.08)<BJ23,0,(+BI23*0.08)-BJ23) -> 0 | BQ23: =IF(BI23<>0,+BJ23/BI23,0) -> 0
A24: 5824 | B24: Faucher-Lavallee David | BI24: =+D24+H24+L24+P24+T24+X24+AB24+AF24+AJ24+AN24+AR24+AV24+AZ24+BD24 -> 0 | BJ24: =+E24+I24+M24+Q24+U24+Y24+AC24+AG24+AK24+AO24+AS24+AW24+BA24+BE24 -> 0 | BK24: =+F24+J24+N24+R24+V25+Z24+AD24+AH24+AL24+AP24+AT24+AX24+BB24+BF24 -> 0 | BL24: =+G24+K24+O24+S24+W24+AA24+AE24+AI24+AM24+AQ24+AU24+AY24+BC24+BG24 -> 0 | BM24: =+E24-F24+G24+I24-J24+K24+M24-N24+O24+Q24-R24+S24+U24-V25+W24+Y24-Z24+AA24+AC24-AD24+AE24 -> 0 | BN24: =+AG24-AH24+AI24+AK24-AL24+AM24+AO24-AP24+AQ24+AS24-AT24+AU24+AW24-AX24+AY24+BA24-BB24+BC24+BE24-BF24+BG24 -> 0 | BO24: =BJ24-BK24+BL24 -> 0 | BP24: =IF((+BI24*0.08)<BJ24,0,(+BI24*0.08)-BJ24) -> 0 | BQ24: =IF(BI24<>0,+BJ24/BI24,0) -> 0
A25: 5734 | B25: Forget Caroline | D25: =442.79 -> 442.79 | E25: =44.27 -> 44.27 | H25: 832 | I25: 83 | L25: 1702.5 | M25: 170 | T25: 1376.5 | U25: 137 | X25: 1681.39 | Y25: 168 | AF25: 1362.84 | AG25: 136 | AJ25: 421.41 | AK25: 42 | AZ25: =298.19+444.36 -> 742.55 | BA25: =30+44 -> 74 | BD25: 228.01 | BE25: 22.8 | BI25: =+D25+H25+L25+P25+T25+X25+AB25+AF25+AJ25+AN25+AR25+AV25+AZ25+BD25 -> 8789.99 | BJ25: =+E25+I25+M25+Q25+U25+Y25+AC25+AG25+AK25+AO25+AS25+AW25+BA25+BE25 -> 877.07 | BK25: =+F25+J25+N25+R25+V26+Z25+AD25+AH25+AL25+AP25+AT25+AX25+BB25+BF25 -> 0 | BL25: =+G25+K25+O25+S25+W25+AA25+AE25+AI25+AM25+AQ25+AU25+AY25+BC25+BG25 -> 0 | BM25: =+E25-F25+G25+I25-J25+K25+M25-N25+O25+Q25-R25+S25+U25-V26+W25+Y25-Z25+AA25+AC25-AD25+AE25 -> 602.27 | BN25: =+AG25-AH25+AI25+AK25-AL25+AM25+AO25-AP25+AQ25+AS25-AT25+AU25+AW25-AX25+AY25+BA25-BB25+BC25+BE25-BF25+BG25 -> 274.8 | BO25: =BJ25-BK25+BL25 -> 877.07 | BP25: =IF((+BI25*0.08)<BJ25,0,(+BI25*0.08)-BJ25) -> 0 | BQ25: =IF(BI25<>0,+BJ25/BI25,0) -> 0.099780546
A26: 5628 | B26: Giorgi david | BI26: =+D26+H26+L26+P26+T26+X26+AB26+AF26+AJ26+AN26+AR26+AV26+AZ26+BD26 -> 0 | BJ26: =+E26+I26+M26+Q26+U26+Y26+AC26+AG26+AK26+AO26+AS26+AW26+BA26+BE26 -> 0 | BK26: =+F26+J26+N26+R26+V27+Z26+AD26+AH26+AL26+AP26+AT26+AX26+BB26+BF26 -> 0 | BL26: =+G26+K26+O26+S26+W26+AA26+AE26+AI26+AM26+AQ26+AU26+AY26+BC26+BG26 -> 0 | BM26: =+E26-F26+G26+I26-J26+K26+M26-N26+O26+Q26-R26+S26+U26-V27+W26+Y26-Z26+AA26+AC26-AD26+AE26 -> 0 | BN26: =+AG26-AH26+AI26+AK26-AL26+AM26+AO26-AP26+AQ26+AS26-AT26+AU26+AW26-AX26+AY26+BA26-BB26+BC26+BE26-BF26+BG26 -> 0 | BO26: =BJ26-BK26+BL26 -> 0 | BP26: =IF((+BI26*0.08)<BJ26,0,(+BI26*0.08)-BJ26) -> 0 | BQ26: =IF(BI26<>0,+BJ26/BI26,0) -> 0
A27: 5675 | B27: Gagnon Sabrina | BI27: =+D27+H27+L27+P27+T27+X27+AB27+AF27+AJ27+AN27+AR27+AV27+AZ27+BD27 -> 0 | BJ27: =+E27+I27+M27+Q27+U27+Y27+AC27+AG27+AK27+AO27+AS27+AW27+BA27+BE27 -> 0 | BK27: =+F27+J27+N27+R27+V28+Z27+AD27+AH27+AL27+AP27+AT27+AX27+BB27+BF27 -> 0 | BL27: =+G27+K27+O27+S27+W27+AA27+AE27+AI27+AM27+AQ27+AU27+AY27+BC27+BG27 -> 0 | BM27: =+E27-F27+G27+I27-J27+K27+M27-N27+O27+Q27-R27+S27+U27-V28+W27+Y27-Z27+AA27+AC27-AD27+AE27 -> 0 | BN27: =+AG27-AH27+AI27+AK27-AL27+AM27+AO27-AP27+AQ27+AS27-AT27+AU27+AW27-AX27+AY27+BA27-BB27+BC27+BE27-BF27+BG27 -> 0 | BO27: =BJ27-BK27+BL27 -> 0 | BP27: =IF((+BI27*0.08)<BJ27,0,(+BI27*0.08)-BJ27) -> 0 | BQ27: =IF(BI27<>0,+BJ27/BI27,0) -> 0
A28: 5893 | B28: Gallego Camila Maria | D28: =261.83 -> 261.83 | E28: =26.18 -> 26.18 | AF28: 821.76 | AG28: 82.1 | BD28: 400 | BE28: 40 | BI28: =+D28+H28+L28+P28+T28+X28+AB28+AF28+AJ28+AN28+AR28+AV28+AZ28+BD28 -> 1483.59 | BJ28: =+E28+I28+M28+Q28+U28+Y28+AC28+AG28+AK28+AO28+AS28+AW28+BA28+BE28 -> 148.28 | BK28: =+F28+J28+N28+R28+V29+Z28+AD28+AH28+AL28+AP28+AT28+AX28+BB28+BF28 -> 0 | BL28: =+G28+K28+O28+S28+W28+AA28+AE28+AI28+AM28+AQ28+AU28+AY28+BC28+BG28 -> 0 | BM28: =+E28-F28+G28+I28-J28+K28+M28-N28+O28+Q28-R28+S28+U28-V29+W28+Y28-Z28+AA28+AC28-AD28+AE28 -> 26.18 | BN28: =+AG28-AH28+AI28+AK28-AL28+AM28+AO28-AP28+AQ28+AS28-AT28+AU28+AW28-AX28+AY28+BA28-BB28+BC28+BE28-BF28+BG28 -> 122.1 | BO28: =BJ28-BK28+BL28 -> 148.28 | BP28: =IF((+BI28*0.08)<BJ28,0,(+BI28*0.08)-BJ28) -> 0 | BQ28: =IF(BI28<>0,+BJ28/BI28,0) -> 0.099946751
A29: 93127 | B29: George Youri | BI29: =+D29+H29+L29+P29+T29+X29+AB29+AF29+AJ29+AN29+AR29+AV29+AZ29+BD29 -> 0 | BJ29: =+E29+I29+M29+Q29+U29+Y29+AC29+AG29+AK29+AO29+AS29+AW29+BA29+BE29 -> 0 | BK29: =+F29+J29+N29+R29+V30+Z29+AD29+AH29+AL29+AP29+AT29+AX29+BB29+BF29 -> 0 | BL29: =+G29+K29+O29+S29+W29+AA29+AE29+AI29+AM29+AQ29+AU29+AY29+BC29+BG29 -> 0 | BM29: =+E29-F29+G29+I29-J29+K29+M29-N29+O29+Q29-R29+S29+U29-V30+W29+Y29-Z29+AA29+AC29-AD29+AE29 -> 0 | BN29: =+AG29-AH29+AI29+AK29-AL29+AM29+AO29-AP29+AQ29+AS29-AT29+AU29+AW29-AX29+AY29+BA29-BB29+BC29+BE29-BF29+BG29 -> 0 | BO29: =BJ29-BK29+BL29 -> 0 | BP29: =IF((+BI29*0.08)<BJ29,0,(+BI29*0.08)-BJ29) -> 0 | BQ29: =IF(BI29<>0,+BJ29/BI29,0) -> 0
A30: 5895 | B30: Grenon Chloe | AB30: 722.47 | AC30: 72.26 | BD30: =472.44+228.01 -> 700.45 | BE30: =22.8+47.24 -> 70.04 | BI30: =+D30+H30+L30+P30+T30+X30+AB30+AF30+AJ30+AN30+AR30+AV30+AZ30+BD30 -> 1422.92 | BJ30: =+E30+I30+M30+Q30+U30+Y30+AC30+AG30+AK30+AO30+AS30+AW30+BA30+BE30 -> 142.3 | BK30: =+F30+J30+N30+R30+V31+Z30+AD30+AH30+AL30+AP30+AT30+AX30+BB30+BF30 -> 0 | BL30: =+G30+K30+O30+S30+W30+AA30+AE30+AI30+AM30+AQ30+AU30+AY30+BC30+BG30 -> 0 | BM30: =+E30-F30+G30+I30-J30+K30+M30-N30+O30+Q30-R30+S30+U30-V31+W30+Y30-Z30+AA30+AC30-AD30+AE30 -> 72.26 | BN30: =+AG30-AH30+AI30+AK30-AL30+AM30+AO30-AP30+AQ30+AS30-AT30+AU30+AW30-AX30+AY30+BA30-BB30+BC30+BE30-BF30+BG30 -> 70.04 | BO30: =BJ30-BK30+BL30 -> 142.3 | BP30: =IF((+BI30*0.08)<BJ30,0,(+BI30*0.08)-BJ30) -> 0 | BQ30: =IF(BI30<>0,+BJ30/BI30,0) -> 0.10000562
A31: 93606 | B31: Guerin Valerie | BI31: =+D31+H31+L31+P31+T31+X31+AB31+AF31+AJ31+AN31+AR31+AV31+AZ31+BD31 -> 0 | BJ31: =+E31+I31+M31+Q31+U31+Y31+AC31+AG31+AK31+AO31+AS31+AW31+BA31+BE31 -> 0 | BK31: =+F31+J31+N31+R31+V32+Z31+AD31+AH31+AL31+AP31+AT31+AX31+BB31+BF31 -> 0 | BL31: =+G31+K31+O31+S31+W31+AA31+AE31+AI31+AM31+AQ31+AU31+AY31+BC31+BG31 -> 0 | BM31: =+E31-F31+G31+I31-J31+K31+M31-N31+O31+Q31-R31+S31+U31-V32+W31+Y31-Z31+AA31+AC31-AD31+AE31 -> 0 | BN31: =+AG31-AH31+AI31+AK31-AL31+AM31+AO31-AP31+AQ31+AS31-AT31+AU31+AW31-AX31+AY31+BA31-BB31+BC31+BE31-BF31+BG31 -> 0 | BO31: =BJ31-BK31+BL31 -> 0 | BP31: =IF((+BI31*0.08)<BJ31,0,(+BI31*0.08)-BJ31) -> 0 | BQ31: =IF(BI31<>0,+BJ31/BI31,0) -> 0
A32: 92908 | B32: Hammond Kelly-Ann | BI32: =+D32+H32+L32+P32+T32+X32+AB32+AF32+AJ32+AN32+AR32+AV32+AZ32+BD32 -> 0 | BJ32: =+E32+I32+M32+Q32+U32+Y32+AC32+AG32+AK32+AO32+AS32+AW32+BA32+BE32 -> 0 | BK32: =+F32+J32+N32+R32+V33+Z32+AD32+AH32+AL32+AP32+AT32+AX32+BB32+BF32 -> 0 | BL32: =+G32+K32+O32+S32+W32+AA32+AE32+AI32+AM32+AQ32+AU32+AY32+BC32+BG32 -> 0 | BM32: =+E32-F32+G32+I32-J32+K32+M32-N32+O32+Q32-R32+S32+U32-V33+W32+Y32-Z32+AA32+AC32-AD32+AE32 -> 0 | BN32: =+AG32-AH32+AI32+AK32-AL32+AM32+AO32-AP32+AQ32+AS32-AT32+AU32+AW32-AX32+AY32+BA32-BB32+BC32+BE32-BF32+BG32 -> 0 | BO32: =BJ32-BK32+BL32 -> 0 | BP32: =IF((+BI32*0.08)<BJ32,0,(+BI32*0.08)-BJ32) -> 0 | BQ32: =IF(BI32<>0,+BJ32/BI32,0) -> 0
A33: 4100 | B33: Jacques Ylan Michel | BI33: =+D33+H33+L33+P33+T33+X33+AB33+AF33+AJ33+AN33+AR33+AV33+AZ33+BD33 -> 0 | BJ33: =+E33+I33+M33+Q33+U33+Y33+AC33+AG33+AK33+AO33+AS33+AW33+BA33+BE33 -> 0 | BK33: =+F33+J33+N33+R33+V34+Z33+AD33+AH33+AL33+AP33+AT33+AX33+BB33+BF33 -> 0 | BL33: =+G33+K33+O33+S33+W33+AA33+AE33+AI33+AM33+AQ33+AU33+AY33+BC33+BG33 -> 0 | BM33: =+E33-F33+G33+I33-J33+K33+M33-N33+O33+Q33-R33+S33+U33-V34+W33+Y33-Z33+AA33+AC33-AD33+AE33 -> 0 | BN33: =+AG33-AH33+AI33+AK33-AL33+AM33+AO33-AP33+AQ33+AS33-AT33+AU33+AW33-AX33+AY33+BA33-BB33+BC33+BE33-BF33+BG33 -> 0 | BO33: =BJ33-BK33+BL33 -> 0 | BP33: =IF((+BI33*0.08)<BJ33,0,(+BI33*0.08)-BJ33) -> 0 | BQ33: =IF(BI33<>0,+BJ33/BI33,0) -> 0
A34: 5131 | B34: Katsenis Spiro | H34: 534.8 | I34: 54.6 | L34: =229.25+285.5 -> 514.75 | M34: =22.92+29 -> 51.92 | P34: 501.93 | Q34: 50.19 | T34: =270.42+767.75 -> 1038.17 | U34: =27+76.77 -> 103.77 | X34: 303.12 | Y34: 30.31 | AJ34: =298.5 -> 298.5 | AK34: =29.85 -> 29.85 | AN34: =251.83 -> 251.83 | AO34: =25.18 -> 25.18 | AR34: =176.75+330.66 -> 507.41 | AS34: =18+33 -> 51 | AV34: 251.83 | AW34: 25.18 | AZ34: =214.25+298.19 -> 512.44 | BA34: =21.42+30 -> 51.42 | BI34: =+D34+H34+L34+P34+T34+X34+AB34+AF34+AJ34+AN34+AR34+AV34+AZ34+BD34 -> 4714.78 | BJ34: =+E34+I34+M34+Q34+U34+Y34+AC34+AG34+AK34+AO34+AS34+AW34+BA34+BE34 -> 473.42 | BK34: =+F34+J34+N34+R34+V35+Z34+AD34+AH34+AL34+AP34+AT34+AX34+BB34+BF34 -> 0 | BL34: =+G34+K34+O34+S34+W34+AA34+AE34+AI34+AM34+AQ34+AU34+AY34+BC34+BG34 -> 0 | BM34: =+E34-F34+G34+I34-J34+K34+M34-N34+O34+Q34-R34+S34+U34-V35+W34+Y34-Z34+AA34+AC34-AD34+AE34 -> 290.79 | BN34: =+AG34-AH34+AI34+AK34-AL34+AM34+AO34-AP34+AQ34+AS34-AT34+AU34+AW34-AX34+AY34+BA34-BB34+BC34+BE34-BF34+BG34 -> 182.63 | BO34: =BJ34-BK34+BL34 -> 473.42 | BP34: =IF((+BI34*0.08)<BJ34,0,(+BI34*0.08)-BJ34) -> 0 | BQ34: =IF(BI34<>0,+BJ34/BI34,0) -> 0.1004119
A35: 92484 | B35: Latulippe Stephane | D35: =427.27 -> 427.27 | E35: 42.75 | BD35: 200.87 | BE35: 20 | BI35: =+D35+H35+L35+P35+T35+X35+AB35+AF35+AJ35+AN35+AR35+AV35+AZ35+BD35 -> 628.14 | BJ35: =+E35+I35+M35+Q35+U35+Y35+AC35+AG35+AK35+AO35+AS35+AW35+BA35+BE35 -> 62.75 | BK35: =+F35+J35+N35+R35+V36+Z35+AD35+AH35+AL35+AP35+AT35+AX35+BB35+BF35 -> 0 | BL35: =+G35+K35+O35+S35+W35+AA35+AE35+AI35+AM35+AQ35+AU35+AY35+BC35+BG35 -> 0 | BM35: =+E35-F35+G35+I35-J35+K35+M35-N35+O35+Q35-R35+S35+U35-V36+W35+Y35-Z35+AA35+AC35-AD35+AE35 -> 42.75 | BN35: =+AG35-AH35+AI35+AK35-AL35+AM35+AO35-AP35+AQ35+AS35-AT35+AU35+AW35-AX35+AY35+BA35-BB35+BC35+BE35-BF35+BG35 -> 20 | BO35: =BJ35-BK35+BL35 -> 62.75 | BP35: =IF((+BI35*0.08)<BJ35,0,(+BI35*0.08)-BJ35) -> 0 | BQ35: =IF(BI35<>0,+BJ35/BI35,0) -> 0.099898112
A36: 5534 | B36: Labreche emilie | BI36: =+D36+H36+L36+P36+T36+X36+AB36+AF36+AJ36+AN36+AR36+AV36+AZ36+BD36 -> 0 | BJ36: =+E36+I36+M36+Q36+U36+Y36+AC36+AG36+AK36+AO36+AS36+AW36+BA36+BE36 -> 0 | BK36: =+F36+J36+N36+R36+V37+Z36+AD36+AH36+AL36+AP36+AT36+AX36+BB36+BF36 -> 0 | BL36: =+G36+K36+O36+S36+W36+AA36+AE36+AI36+AM36+AQ36+AU36+AY36+BC36+BG36 -> 0 | BM36: =+E36-F36+G36+I36-J36+K36+M36-N36+O36+Q36-R36+S36+U36-V37+W36+Y36-Z36+AA36+AC36-AD36+AE36 -> 0 | BN36: =+AG36-AH36+AI36+AK36-AL36+AM36+AO36-AP36+AQ36+AS36-AT36+AU36+AW36-AX36+AY36+BA36-BB36+BC36+BE36-BF36+BG36 -> 0 | BO36: =BJ36-BK36+BL36 -> 0 | BP36: =IF((+BI36*0.08)<BJ36,0,(+BI36*0.08)-BJ36) -> 0 | BQ36: =IF(BI36<>0,+BJ36/BI36,0) -> 0
A37: 5812 | B37: Leclair Isabelle | D37: =708.48 -> 708.48 | E37: 70.84 | L37: =285.5+229.25 -> 514.75 | M37: =29+22.92 -> 51.92 | P37: 954.12 | Q37: 95 | X37: =303.12+537.59 -> 840.71 | Y37: =30.31+53.75 -> 84.06 | AB37: =722.46+1855.2 -> 2577.66 | AC37: =72.26+185 -> 257.26 | AF37: 1362.83 | AG37: 136 | AJ37: =136.5+68.01+374.87+295.44 -> 874.82 | AK37: =13.65+6.8+37.48+29 -> 86.93 | AZ37: =214.25+298.19 -> 512.44 | BA37: =21.42+30 -> 51.42 | BD37: =472.44+228.01 -> 700.45 | BE37: =22.8+47.24 -> 70.04 | BI37: =+D37+H37+L37+P37+T37+X37+AB37+AF37+AJ37+AN37+AR37+AV37+AZ37+BD37 -> 9046.26 | BJ37: =+E37+I37+M37+Q37+U37+Y37+AC37+AG37+AK37+AO37+AS37+AW37+BA37+BE37 -> 903.47 | BK37: =+F37+J37+N37+R37+V38+Z37+AD37+AH37+AL37+AP37+AT37+AX37+BB37+BF37 -> 0 | BL37: =+G37+K37+O37+S37+W37+AA37+AE37+AI37+AM37+AQ37+AU37+AY37+BC37+BG37 -> 0 | BM37: =+E37-F37+G37+I37-J37+K37+M37-N37+O37+Q37-R37+S37+U37-V38+W37+Y37-Z37+AA37+AC37-AD37+AE37 -> 559.08 | BN37: =+AG37-AH37+AI37+AK37-AL37+AM37+AO37-AP37+AQ37+AS37-AT37+AU37+AW37-AX37+AY37+BA37-BB37+BC37+BE37-BF37+BG37 -> 344.39 | BO37: =BJ37-BK37+BL37 -> 903.47 | BP37: =IF((+BI37*0.08)<BJ37,0,(+BI37*0.08)-BJ37) -> 0 | BQ37: =IF(BI37<>0,+BJ37/BI37,0) -> 0.099872212
A38: 4101 | B38: Leclerc Karl | BI38: =+D38+H38+L38+P38+T38+X38+AB38+AF38+AJ38+AN38+AR38+AV38+AZ38+BD38 -> 0 | BJ38: =+E38+I38+M38+Q38+U38+Y38+AC38+AG38+AK38+AO38+AS38+AW38+BA38+BE38 -> 0 | BK38: =+F38+J38+N38+R38+V39+Z38+AD38+AH38+AL38+AP38+AT38+AX38+BB38+BF38 -> 0 | BL38: =+G38+K38+O38+S38+W38+AA38+AE38+AI38+AM38+AQ38+AU38+AY38+BC38+BG38 -> 0 | BM38: =+E38-F38+G38+I38-J38+K38+M38-N38+O38+Q38-R38+S38+U38-V39+W38+Y38-Z38+AA38+AC38-AD38+AE38 -> 0 | BN38: =+AG38-AH38+AI38+AK38-AL38+AM38+AO38-AP38+AQ38+AS38-AT38+AU38+AW38-AX38+AY38+BA38-BB38+BC38+BE38-BF38+BG38 -> 0 | BO38: =BJ38-BK38+BL38 -> 0 | BP38: =IF((+BI38*0.08)<BJ38,0,(+BI38*0.08)-BJ38) -> 0 | BQ38: =IF(BI38<>0,+BJ38/BI38,0) -> 0
A39: 4600 | B39: Lefebvre Martin | BI39: =+D39+H39+L39+P39+T39+X39+AB39+AF39+AJ39+AN39+AR39+AV39+AZ39+BD39 -> 0 | BJ39: =+E39+I39+M39+Q39+U39+Y39+AC39+AG39+AK39+AO39+AS39+AW39+BA39+BE39 -> 0 | BK39: =+F39+J39+N39+R39+V40+Z39+AD39+AH39+AL39+AP39+AT39+AX39+BB39+BF39 -> 0 | BL39: =+G39+K39+O39+S39+W39+AA39+AE39+AI39+AM39+AQ39+AU39+AY39+BC39+BG39 -> 0 | BM39: =+E39-F39+G39+I39-J39+K39+M39-N39+O39+Q39-R39+S39+U39-V40+W39+Y39-Z39+AA39+AC39-AD39+AE39 -> 0 | BN39: =+AG39-AH39+AI39+AK39-AL39+AM39+AO39-AP39+AQ39+AS39-AT39+AU39+AW39-AX39+AY39+BA39-BB39+BC39+BE39-BF39+BG39 -> 0 | BO39: =BJ39-BK39+BL39 -> 0 | BP39: =IF((+BI39*0.08)<BJ39,0,(+BI39*0.08)-BJ39) -> 0 | BQ39: =IF(BI39<>0,+BJ39/BI39,0) -> 0
A40: 4717 | B40: Letourneau Sarah | BI40: =+D40+H40+L40+P40+T40+X40+AB40+AF40+AJ40+AN40+AR40+AV40+AZ40+BD40 -> 0 | BJ40: =+E40+I40+M40+Q40+U40+Y40+AC40+AG40+AK40+AO40+AS40+AW40+BA40+BE40 -> 0 | BK40: =+F40+J40+N40+R40+V41+Z40+AD40+AH40+AL40+AP40+AT40+AX40+BB40+BF40 -> 0 | BL40: =+G40+K40+O40+S40+W40+AA40+AE40+AI40+AM40+AQ40+AU40+AY40+BC40+BG40 -> 0 | BM40: =+E40-F40+G40+I40-J40+K40+M40-N40+O40+Q40-R40+S40+U40-V41+W40+Y40-Z40+AA40+AC40-AD40+AE40 -> 0 | BN40: =+AG40-AH40+AI40+AK40-AL40+AM40+AO40-AP40+AQ40+AS40-AT40+AU40+AW40-AX40+AY40+BA40-BB40+BC40+BE40-BF40+BG40 -> 0 | BO40: =BJ40-BK40+BL40 -> 0 | BP40: =IF((+BI40*0.08)<BJ40,0,(+BI40*0.08)-BJ40) -> 0 | BQ40: =IF(BI40<>0,+BJ40/BI40,0) -> 0
A41: 400 | B41: Lim Mathy | BI41: =+D41+H41+L41+P41+T41+X41+AB41+AF41+AJ41+AN41+AR41+AV41+AZ41+BD41 -> 0 | BJ41: =+E41+I41+M41+Q41+U41+Y41+AC41+AG41+AK41+AO41+AS41+AW41+BA41+BE41 -> 0 | BK41: =+F41+J41+N41+R41+V42+Z41+AD41+AH41+AL41+AP41+AT41+AX41+BB41+BF41 -> 0 | BL41: =+G41+K41+O41+S41+W41+AA41+AE41+AI41+AM41+AQ41+AU41+AY41+BC41+BG41 -> 0 | BM41: =+E41-F41+G41+I41-J41+K41+M41-N41+O41+Q41-R41+S41+U41-V42+W41+Y41-Z41+AA41+AC41-AD41+AE41 -> 0 | BN41: =+AG41-AH41+AI41+AK41-AL41+AM41+AO41-AP41+AQ41+AS41-AT41+AU41+AW41-AX41+AY41+BA41-BB41+BC41+BE41-BF41+BG41 -> 0 | BO41: =BJ41-BK41+BL41 -> 0 | BP41: =IF((+BI41*0.08)<BJ41,0,(+BI41*0.08)-BJ41) -> 0 | BQ41: =IF(BI41<>0,+BJ41/BI41,0) -> 0
...
